### YamlMime:UniversalReference
ms.openlocfilehash: 777051058935475aebf2055932882ec0cd21fea9
ms.sourcegitcommit: efa2d98deffe8a0d41a8d63f9f07aa720862e6ab
ms.translationtype: MT
ms.contentlocale: ru-RU
ms.lasthandoff: 12/13/2018
ms.locfileid: "52135179"
items:
- uid: azure-servicefabric.TestErrorChaosEvent
  name: TestErrorChaosEvent
  fullName: TestErrorChaosEvent
  children:
  - azure-servicefabric.TestErrorChaosEvent.reason
  langs:
  - typeScript
  type: interface
  summary: >-
    <span data-ttu-id="ff36d-101">Описывает события Chaos, которая создается при возникновении непредвиденных события в модуле Chaos.</span><span class="sxs-lookup"><span data-stu-id="ff36d-101">Describes a Chaos event that gets generated when an unexpected event occurs in the Chaos engine.</span></span>

    <span data-ttu-id="ff36d-102">Например из-за моментального снимка кластера, не согласована, во время сущности с ошибками, Chaos найти что сущность уже сбой — что было бы непредвиденное событие.</span><span class="sxs-lookup"><span data-stu-id="ff36d-102">For example, due to the cluster snapshot being inconsistent, while faulting an entity, Chaos found that the entity was already faulted -- which would be an unexpected event.</span></span>
  extends:
    name: azure-servicefabric.ChaosEvent
  package: azure-servicefabric
- uid: azure-servicefabric.TestErrorChaosEvent.reason
  name: reason
  fullName: reason
  children: []
  langs:
  - typeScript
  type: property
  summary: <span data-ttu-id="ff36d-103">Описывает, почему TestErrorChaosEvent был создан.</span><span class="sxs-lookup"><span data-stu-id="ff36d-103">Describes why TestErrorChaosEvent was generated.</span></span> <span data-ttu-id="ff36d-104">К примеру Chaos пытается сбоя секции, но обнаруживает, что раздел больше не является отказоустойчивым, а затем получает созданный TestErrorEvent причина сообщение о том, что раздел не является отказоустойчивым.</span><span class="sxs-lookup"><span data-stu-id="ff36d-104">For example, Chaos tries to fault a partition but finds that the partition is no longer fault tolerant, then a TestErrorEvent gets generated with the reason stating that the partition is not fault tolerant.</span></span>
  optional: true
  syntax:
    content: 'reason?: string'
    return:
      type:
      - string
  package: azure-servicefabric
references:
- uid: azure-servicefabric.ChaosEvent
  name: ChaosEvent
  spec.typeScript:
  - name: ChaosEvent
    fullName: ChaosEvent
    uid: azure-servicefabric.ChaosEvent
